2014-01-11 03:22:23,151 ERROR: Internal Error __init__ [in /usr/local/lib/python2.7/dist-packages/flask_restful/__init__.py:167]
Traceback (most recent call last):
  File "/usr/local/lib/python2.7/dist-packages/flask/app.py", line 1475, in full_dispatch_request
    rv = self.dispatch_request()
  File "/usr/local/lib/python2.7/dist-packages/flask/app.py", line 1461, in dispatch_request
    return self.view_functions[rule.endpoint](**req.view_args)
  File "/usr/local/lib/python2.7/dist-packages/flask_restful/__init__.py", line 252, in wrapper
    resp = resource(*args, **kwargs)
  File "/usr/local/lib/python2.7/dist-packages/flask/views.py", line 84, in view
    return self.dispatch_request(*args, **kwargs)
  File "/usr/local/lib/python2.7/dist-packages/flask_restful/__init__.py", line 332, in dispatch_request
    resp = meth(*args, **kwargs)
  File "./app.py", line 84, in post
    return jsonify(result = NewsData.post_tags(news_list),
  File "/home/k/Programs/python/news_classification/helpers.py", line 138, in post_tags
    success_ids = [news for news in new_data if not news.get("id") in scraped]
NameError: global name 'new_data' is not defined
2014-01-11 03:22:40,865 ERROR: An error occurred custom_logging [in /home/k/Programs/python/news_classification/scrape/custom_logging.py:36]
2014-01-11 03:22:40,865 DEBUG: A value for debugging custom_logging [in /home/k/Programs/python/news_classification/scrape/custom_logging.py:37]
2014-01-11 03:22:40,865 WARNING: A warning occurred (42 apples) custom_logging [in /home/k/Programs/python/news_classification/scrape/custom_logging.py:38]
2014-01-11 03:22:40,866 INFO: My App custom_logging [in /home/k/Programs/python/news_classification/scrape/custom_logging.py:39]
2014-01-11 03:22:43,120 ERROR: Internal Error __init__ [in /usr/local/lib/python2.7/dist-packages/flask_restful/__init__.py:167]
Traceback (most recent call last):
  File "/usr/local/lib/python2.7/dist-packages/flask/app.py", line 1475, in full_dispatch_request
    rv = self.dispatch_request()
  File "/usr/local/lib/python2.7/dist-packages/flask/app.py", line 1461, in dispatch_request
    return self.view_functions[rule.endpoint](**req.view_args)
  File "/usr/local/lib/python2.7/dist-packages/flask_restful/__init__.py", line 252, in wrapper
    resp = resource(*args, **kwargs)
  File "/usr/local/lib/python2.7/dist-packages/flask/views.py", line 84, in view
    return self.dispatch_request(*args, **kwargs)
  File "/usr/local/lib/python2.7/dist-packages/flask_restful/__init__.py", line 332, in dispatch_request
    resp = meth(*args, **kwargs)
  File "./app.py", line 84, in post
    return jsonify(result = NewsData.post_tags(news_list),
  File "/home/k/Programs/python/news_classification/helpers.py", line 138, in post_tags
    success_ids = [news for news in news_data if not news.get("id") in scraped]
NameError: global name 'news_data' is not defined
2014-01-11 03:23:05,304 ERROR: An error occurred custom_logging [in /home/k/Programs/python/news_classification/scrape/custom_logging.py:36]
2014-01-11 03:23:05,304 DEBUG: A value for debugging custom_logging [in /home/k/Programs/python/news_classification/scrape/custom_logging.py:37]
2014-01-11 03:23:05,304 WARNING: A warning occurred (42 apples) custom_logging [in /home/k/Programs/python/news_classification/scrape/custom_logging.py:38]
2014-01-11 03:23:05,304 INFO: My App custom_logging [in /home/k/Programs/python/news_classification/scrape/custom_logging.py:39]
2014-01-11 03:23:06,810 ERROR: Internal Error __init__ [in /usr/local/lib/python2.7/dist-packages/flask_restful/__init__.py:167]
Traceback (most recent call last):
  File "/usr/local/lib/python2.7/dist-packages/flask/app.py", line 1475, in full_dispatch_request
    rv = self.dispatch_request()
  File "/usr/local/lib/python2.7/dist-packages/flask/app.py", line 1461, in dispatch_request
    return self.view_functions[rule.endpoint](**req.view_args)
  File "/usr/local/lib/python2.7/dist-packages/flask_restful/__init__.py", line 252, in wrapper
    resp = resource(*args, **kwargs)
  File "/usr/local/lib/python2.7/dist-packages/flask/views.py", line 84, in view
    return self.dispatch_request(*args, **kwargs)
  File "/usr/local/lib/python2.7/dist-packages/flask_restful/__init__.py", line 332, in dispatch_request
    resp = meth(*args, **kwargs)
  File "./app.py", line 84, in post
    return jsonify(result = NewsData.post_tags(news_list),
  File "/home/k/Programs/python/news_classification/helpers.py", line 138, in post_tags
    success_ids = [news for news in news_list if not news.get("id") in scraped]
NameError: global name 'scraped' is not defined
2014-01-11 03:23:29,732 ERROR: An error occurred custom_logging [in /home/k/Programs/python/news_classification/scrape/custom_logging.py:36]
2014-01-11 03:23:29,732 DEBUG: A value for debugging custom_logging [in /home/k/Programs/python/news_classification/scrape/custom_logging.py:37]
2014-01-11 03:23:29,732 WARNING: A warning occurred (42 apples) custom_logging [in /home/k/Programs/python/news_classification/scrape/custom_logging.py:38]
2014-01-11 03:23:29,733 INFO: My App custom_logging [in /home/k/Programs/python/news_classification/scrape/custom_logging.py:39]
2014-01-11 03:26:40,613 ERROR: An error occurred custom_logging [in /home/k/Programs/python/news_classification/scrape/custom_logging.py:36]
2014-01-11 03:26:40,613 DEBUG: A value for debugging custom_logging [in /home/k/Programs/python/news_classification/scrape/custom_logging.py:37]
2014-01-11 03:26:40,613 WARNING: A warning occurred (42 apples) custom_logging [in /home/k/Programs/python/news_classification/scrape/custom_logging.py:38]
2014-01-11 03:26:40,613 INFO: My App custom_logging [in /home/k/Programs/python/news_classification/scrape/custom_logging.py:39]
2014-01-11 03:27:21,146 ERROR: An error occurred custom_logging [in /home/k/Programs/python/news_classification/scrape/custom_logging.py:36]
2014-01-11 03:27:21,146 DEBUG: A value for debugging custom_logging [in /home/k/Programs/python/news_classification/scrape/custom_logging.py:37]
2014-01-11 03:27:21,146 WARNING: A warning occurred (42 apples) custom_logging [in /home/k/Programs/python/news_classification/scrape/custom_logging.py:38]
2014-01-11 03:27:21,146 INFO: My App custom_logging [in /home/k/Programs/python/news_classification/scrape/custom_logging.py:39]
2014-01-11 03:39:07,160 ERROR: An error occurred custom_logging [in /home/k/Programs/python/news_classification/scrape/custom_logging.py:36]
2014-01-11 03:39:07,160 DEBUG: A value for debugging custom_logging [in /home/k/Programs/python/news_classification/scrape/custom_logging.py:37]
2014-01-11 03:39:07,161 WARNING: A warning occurred (42 apples) custom_logging [in /home/k/Programs/python/news_classification/scrape/custom_logging.py:38]
2014-01-11 03:39:07,161 INFO: My App custom_logging [in /home/k/Programs/python/news_classification/scrape/custom_logging.py:39]
2014-01-11 03:39:07,495 ERROR: An error occurred custom_logging [in /home/k/Programs/python/news_classification/scrape/custom_logging.py:36]
2014-01-11 03:39:07,495 DEBUG: A value for debugging custom_logging [in /home/k/Programs/python/news_classification/scrape/custom_logging.py:37]
2014-01-11 03:39:07,495 WARNING: A warning occurred (42 apples) custom_logging [in /home/k/Programs/python/news_classification/scrape/custom_logging.py:38]
2014-01-11 03:39:07,495 INFO: My App custom_logging [in /home/k/Programs/python/news_classification/scrape/custom_logging.py:39]
2014-01-13 02:26:44,728 ERROR: An error occurred custom_logging [in /home/k/Programs/python/news_classification/scrape/custom_logging.py:36]
2014-01-13 02:26:44,752 DEBUG: A value for debugging custom_logging [in /home/k/Programs/python/news_classification/scrape/custom_logging.py:37]
2014-01-13 02:26:44,753 WARNING: A warning occurred (42 apples) custom_logging [in /home/k/Programs/python/news_classification/scrape/custom_logging.py:38]
2014-01-13 02:26:44,753 INFO: My App custom_logging [in /home/k/Programs/python/news_classification/scrape/custom_logging.py:39]
2014-01-13 02:26:45,070 ERROR: An error occurred custom_logging [in /home/k/Programs/python/news_classification/scrape/custom_logging.py:36]
2014-01-13 02:26:45,071 DEBUG: A value for debugging custom_logging [in /home/k/Programs/python/news_classification/scrape/custom_logging.py:37]
2014-01-13 02:26:45,071 WARNING: A warning occurred (42 apples) custom_logging [in /home/k/Programs/python/news_classification/scrape/custom_logging.py:38]
2014-01-13 02:26:45,071 INFO: My App custom_logging [in /home/k/Programs/python/news_classification/scrape/custom_logging.py:39]
2014-01-13 02:27:54,495 ERROR: An error occurred custom_logging [in /home/k/Programs/python/news_classification/scrape/custom_logging.py:36]
2014-01-13 02:27:54,495 DEBUG: A value for debugging custom_logging [in /home/k/Programs/python/news_classification/scrape/custom_logging.py:37]
2014-01-13 02:27:54,496 WARNING: A warning occurred (42 apples) custom_logging [in /home/k/Programs/python/news_classification/scrape/custom_logging.py:38]
2014-01-13 02:27:54,496 INFO: My App custom_logging [in /home/k/Programs/python/news_classification/scrape/custom_logging.py:39]
2014-01-13 02:27:54,702 ERROR: An error occurred custom_logging [in /home/k/Programs/python/news_classification/scrape/custom_logging.py:36]
2014-01-13 02:27:54,702 DEBUG: A value for debugging custom_logging [in /home/k/Programs/python/news_classification/scrape/custom_logging.py:37]
2014-01-13 02:27:54,703 WARNING: A warning occurred (42 apples) custom_logging [in /home/k/Programs/python/news_classification/scrape/custom_logging.py:38]
2014-01-13 02:27:54,703 INFO: My App custom_logging [in /home/k/Programs/python/news_classification/scrape/custom_logging.py:39]
2014-01-13 02:28:44,764 ERROR: An error occurred custom_logging [in /home/k/Programs/python/news_classification/scrape/custom_logging.py:36]
